# üìã Rapport de Validation - User-Service SkillForge AI

**Date de g√©n√©ration** : 04/09/2025 12:29:24  
**Dur√©e totale** : 112.83 secondes  
**Statut global** : ‚ùå √âCHECS D√âTECT√âS

## üìä R√©sum√© des M√©triques

| M√©trique | Valeur |
|----------|--------|
| **Tests totaux** | 7 |
| **Tests r√©ussis** | 2 |
| **Tests √©chou√©s** | 3 |
| **Avertissements** | 1 |
| **Taux de succ√®s** | 28.6% |

## üîç D√©tail des Tests

### 1Ô∏è‚É£ Connexion PostgreSQL - ‚úÖ PASS

**Description** : Connexion r√©ussie √† PostgreSQL. Version: PostgreSQL 16.9 on x86_64-pc-linux-gnu, compiled by Debian clang version 12.0.1, 64-bit

**M√©triques** :
- **connection_time** : 2.245
- **database_size** : 7628 kB
- **active_connections** : 1
- **pool_size** : 1-5

### 2Ô∏è‚É£ Migrations Alembic - ‚úÖ PASS

**Description** : Migrations appliqu√©es avec succ√®s. 0 migrations trouv√©es.

**M√©triques** :
- **execution_time** : 7.231
- **migration_count** : 0
- **current_revision** : 
- **upgrade_output** : 

### 3Ô∏è‚É£ Sch√©ma Base de Donn√©es - ‚ö†Ô∏è WARN

**Description** : Tables trouv√©es: 1/7. Manquantes: ['users', 'user_settings', 'user_sessions', 'company_profiles', 'team_members', 'subscriptions']

**M√©triques** :
- **total_tables** : 1
- **expected_tables** : 7
- **missing_tables** : 6 √©l√©ments
- **extra_tables** : 0 √©l√©ments
- **table_analyses** : {}
- **index_count** : 1

### 4Ô∏è‚É£ Tests Unitaires - ‚ùå FAIL

**Description** : Erreur pytest (code 4)

**M√©triques** :
- **execution_time** : 2.677
- **exit_code** : 4
- **coverage_percentage** : 0
- **test_summary** : 0 √©l√©ments
- **coverage_data** : {}
- **output_preview** : 

### 5Ô∏è‚É£ D√©marrage Serveur - ‚ùå FAIL

**Description** : Serveur n'a pas d√©marr√© dans les 30s

**M√©triques** :
- **startup_time** : 98.145
- **timeout** : 30

**Erreur** :
```
Traceback (most recent call last):
  File "<frozen runpy>", line 198, in _run_module_as_main
  File "<frozen runpy>", line 88, in _run_code
  File "C:\Users\DELL\AppData\Local\Programs\Python\Python313\Lib\site-packages\uvicorn\__main__.py", line 4, in <module>
    uvicorn.main()
    ~~~~~~~~~~~~^^
  File "C:\Users\DELL\AppData\Local\Programs\Python\Python313\Lib\site-packages\click\core.py", line 1442, in __call__
    return self.main(*args, **kwargs)
           ~~~~~~~~~^^^^^^^^^^^^^^^^^
  File "C:\Users\DELL\AppData\Local\Programs\Python\Python313\Lib\site-packages\click\core.py", line 1363, in main
    rv = self.invoke(ctx)
  File "C:\Users\DELL\AppData\Local\Programs\Python\Python313\Lib\site-packages\click\core.py", line 1226, in invoke
    return ctx.invoke(self.callback, **ctx.params)
           ~~~~~~~~~~^^^^^^^^^^^^^^^^^^^^^^^^^^^^^
  File "C:\Users\DELL\AppData\Local\Programs\Python\Python313\Lib\site-packages\click\core.py", line 794, in invoke
    return callback(*args, **kwargs)
  File "C:\Users\DELL\AppData\Local\Programs\Python\Python313\Lib\site-packages\uvicorn\main.py", line 416, in main
    run(
    ~~~^
        app,
        ^^^^
    ...<45 lines>...
        h11_max_incomplete_event_size=h11_max_incomplete_event_size,
        ^^^^^^^^^^^^^^^^^^^^^^^^^^^^^^^^^^^^^^^^^^^^^^^^^^^^^^^^^^^^
    )
    ^
  File "C:\Users\DELL\AppData\Local\Programs\Python\Python313\Lib\site-packages\uvicorn\main.py", line 587, in run
    server.run()
    ~~~~~~~~~~^^
  File "C:\Users\DELL\AppData\Local\Programs\Python\Python313\Lib\site-packages\uvicorn\server.py", line 61, in run
    return asyncio.run(self.serve(sockets=sockets))
           ~~~~~~~~~~~^^^^^^^^^^^^^^^^^^^^^^^^^^^^^
  File "C:\Users\DELL\AppData\Local\Programs\Python\Python313\Lib\asyncio\runners.py", line 195, in run
    return runner.run(main)
           ~~~~~~~~~~^^^^^^
  File "C:\Users\DELL\AppData\Local\Programs\Python\Python313\Lib\asyncio\runners.py", line 118, in run
    return self._loop.run_until_complete(task)
           ~~~~~~~~~~~~~~~~~~~~~~~~~~~~~^^^^^^
  File "C:\Users\DELL\AppData\Local\Programs\Python\Python313\Lib\asyncio\base_events.py", line 725, in run_until_complete
    return future.result()
           ~~~~~~~~~~~~~^^
  File "C:\Users\DELL\AppData\Local\Programs\Python\Python313\Lib\site-packages\uvicorn\server.py", line 68, in serve
    config.load()
    ~~~~~~~~~~~^^
  File "C:\Users\DELL\AppData\Local\Programs\Python\Python313\Lib\site-packages\uvicorn\config.py", line 467, in load
    self.loaded_app = import_from_string(self.app)
                      ~~~~~~~~~~~~~~~~~~^^^^^^^^^^
  File "C:\Users\DELL\AppData\Local\Programs\Python\Python313\Lib\site-packages\uvicorn\importer.py", line 21, in import_from_string
    module = importlib.import_module(module_str)
  File "C:\Users\DELL\AppData\Local\Programs\Python\Python313\Lib\importlib\__init__.py", line 88, in import_module
    return _bootstrap._gcd_import(name[level:], package, level)
           ~~~~~~~~~~~~~~~~~~~~~~^^^^^^^^^^^^^^^^^^^^^^^^^^^^^^
  File "<frozen importlib._bootstrap>", line 1387, in _gcd_import
  File "<frozen importlib._bootstrap>", line 1360, in _find_and_load
  File "<frozen importlib._bootstrap>", line 1331, in _find_and_load_unlocked
  File "<frozen importlib._bootstrap>", line 935, in _load_unlocked
  File "<frozen importlib._bootstrap_external>", line 1026, in exec_module
  File "<frozen importlib._bootstrap>", line 488, in _call_with_frames_removed
  File "C:\Users\DELL\Documents\GitHub\skillforge-ai-monorepo\apps\backend\user-service\main.py", line 17, in <module>
    from app.api.v1 import api_router
  File "C:\Users\DELL\Documents\GitHub\skillforge-ai-monorepo\apps\backend\user-service\app\api\__init__.py", line 5, in <module>
    from .v1 import api_router
  File "C:\Users\DELL\Documents\GitHub\skillforge-ai-monorepo\apps\backend\user-service\app\api\v1\__init__.py", line 7, in <module>
    from .endpoints import auth_router, users_router, companies_router
  File "C:\Users\DELL\Documents\GitHub\skillforge-ai-monorepo\apps\backend\user-service\app\api\v1\endpoints\__init__.py", line 5, in <module>
    from .auth import router as auth_router
  File "C:\Users\DELL\Documents\GitHub\skillforge-ai-monorepo\apps\backend\user-service\app\api\v1\endpoints\auth.py", line 12, in <module>
    from app.api.dependencies import get_db, rate_limit_dependency
  File "C:\Users\DELL\Documents\GitHub\skillforge-ai-monorepo\apps\backend\user-service\app\api\dependencies.py", line 15, in <module>
    from app.crud import user as user_crud
  File "C:\Users\DELL\Documents\GitHub\skillforge-ai-monorepo\apps\backend\user-service\app\crud\__init__.py", line 6, in <module>
    from .user import CRUDUser, CRUDUserSession, CRUDUserSettings, user, user_session, user_settings
  File "C:\Users\DELL\Documents\GitHub\skillforge-ai-monorepo\apps\backend\user-service\app\crud\user.py", line 12, in <module>
    from app.models.user_simple import User, UserSession, UserSettings, UserRole, UserStatus
ImportError: cannot import name 'UserSession' from 'app.models.user_simple' (C:\Users\DELL\Documents\GitHub\skillforge-ai-monorepo\apps\backend\user-service\app\models\user_simple.py)

```

### 6Ô∏è‚É£ Endpoints API - ‚è≠Ô∏è SKIP

**Description** : Serveur non disponible, tests d'endpoints ignor√©s

### 7Ô∏è‚É£ Validation Donn√©es - ‚ùå FAIL

**Description** : Erreur validation donn√©es: relation "users" does not exist

**Erreur** :
```
relation "users" does not exist
```



## üîß Configuration Syst√®me

| Param√®tre | Valeur |
|-----------|--------|
| **Database URL** | `postgresql+asyncpg://skillforge_user:***@127.0.0.1:5432/skillforge_db` |
| **API Base URL** | `http://127.0.0.1:8000` |
| **Service Path** | `C:\Users\DELL\Documents\GitHub\skillforge-ai-monorepo\apps\backend\user-service` |
| **Python Version** | `3.13.7` |
| **Working Directory** | `C:\Users\DELL\Documents\GitHub\skillforge-ai-monorepo\apps\backend\user-service` |

## üéØ Recommandations

- üî• **CRITIQUE** : Corriger imm√©diatement les tests √©chou√©s avant tout d√©ploiement
- ‚ö†Ô∏è **ATTENTION** : R√©soudre les avertissements pour une meilleure stabilit√©
- üß™ **Tests** : Corriger les tests unitaires - fondamental pour la fiabilit√©
- üìä **Coverage** : Augmenter la couverture de tests (actuel: 0.0%, objectif: 80%+)
- üóÑÔ∏è **Base de donn√©es** : Tables manquantes d√©tect√©es - v√©rifier les migrations
- üåê **API** : Endpoints d√©faillants - impact sur l'int√©gration frontend


## üìù D√©tails Techniques

### Commandes Ex√©cut√©es

1. **Test connexion** : `asyncpg.connect(DATABASE_URL)`
2. **Migrations** : `alembic upgrade head`
3. **Tests unitaires** : `python -m pytest app/tests/ -v --cov=app`
4. **Serveur** : `python -m uvicorn main:app --host 127.0.0.1 --port 8000`
5. **Endpoints** : Tests HTTP avec `httpx.AsyncClient`

### Fichiers G√©n√©r√©s

- `coverage.json` : Rapport de couverture des tests
- `test-validation-report.md` : Ce rapport
- Logs serveur : stdout/stderr du processus uvicorn

### Prochaines √âtapes

1. **Si tous les tests passent** :
   - ‚úÖ Commit des changements : `git add . && git commit -m "feat: user-service ready for production"`
   - ‚úÖ Push vers GitHub : `git push origin feature/user-service`
   - ‚úÖ Cr√©er une Pull Request
   - ‚úÖ D√©clencher le pipeline CI/CD

2. **Si des tests √©chouent** :
   - ‚ùå Corriger les erreurs identifi√©es
   - ‚ùå Relancer la validation : `python validate_service.py`
   - ‚ùå Ne pas committer tant que les tests ne passent pas

---

**Rapport g√©n√©r√© automatiquement par le script de validation SkillForge AI**  
**Version** : 1.0.0  
**Contact** : DevOps Team
